<?xml version="1.0" encoding="utf-8"?>
<!-- This URDF was automatically created by SolidWorks to URDF Exporter! Originally created by Stephen Brawner (brawner@gmail.com) 
     Commit Version: 1.6.0-4-g7f85cfe  Build Version: 1.6.7995.38578
     For more information, please see http://wiki.ros.org/sw_urdf_exporter -->
<robot
  name="Alicia_D_v5_6_gripper_50mm">
 <mujoco>
    <compiler meshdir="../../meshes/Alicia_D_v5_6/gripper_50mm/" discardvisual="false" />
    <contact>
      <exclude body1="base_link" body2="Link1"/>
      <exclude body1="Link1" body2="Link2"/>
      <exclude body1="Link2" body2="Link3"/>
      <exclude body1="Link3" body2="Link4"/>
      <exclude body1="Link4" body2="Link5"/>
      <exclude body1="Link5" body2="Link6"/>
      <exclude body1="Link6" body2="Link7_50mm"/>
      <exclude body1="Link7_50mm" body2="Link8_50mm"/>
    </contact>
  </mujoco>

  <link name="world" />

  <joint name="world_to_base_joint" type="fixed">
    <parent link="world"/>
    <child link="base_link"/>
    <origin xyz="0 0 0" rpy="0 0 3.14" />
  </joint>
  <link
    name="base_link">
    <inertial>
      <origin
        xyz="0.000826234790037257 0.00797844273246933 0.0457675129432198"
        rpy="0 0 0" />
      <mass
        value="0.73396142463988" />
      <inertia
        ixx="0.00138410344771636"
        ixy="5.67201110403939E-05"
        ixz="5.1436016423501E-07"
        iyy="0.00173617223701436"
        iyz="-1.48652204589359E-05"
        izz="0.00274667683203449" />
    </inertial>
    <visual>
      <origin
        xyz="0 0 0"
        rpy="0 0 0" />
      <geometry>
        <mesh
          filename="../../meshes/Alicia_D_v5_6/gripper_50mm/base_link.STL" />
      </geometry>
      <material
        name="">
        <color
          rgba="0.807843137254902 0.843137254901961 0.905882352941176 1" />
      </material>
    </visual>
    <collision>
      <origin
        xyz="0 0 0"
        rpy="0 0 0" />
      <geometry>
        <mesh
          filename="../../meshes/Alicia_D_v5_6/gripper_50mm/base_link.STL" />
      </geometry>
    </collision>
  </link>
  <link
    name="Link1">
    <inertial>
      <origin
        xyz="-0.000230595969793434 -1.29044880293489E-05 0.00303135656120262"
        rpy="0 0 0" />
      <mass
        value="0.195233452997327" />
      <inertia
        ixx="0.000258351125070493"
        ixy="8.79363230470998E-07"
        ixz="-6.87511809706085E-07"
        iyy="0.000149307709386745"
        iyz="-1.07703111237379E-06"
        izz="0.000339791274039062" />
    </inertial>
    <visual>
      <origin
        xyz="0 0 0"
        rpy="0 0 0" />
      <geometry>
        <mesh
          filename="../../meshes/Alicia_D_v5_6/gripper_50mm/Link1.STL" />
      </geometry>
      <material
        name="">
        <color
          rgba="0.796078431372549 0.823529411764706 0.937254901960784 1" />
      </material>
    </visual>
    <collision>
      <origin
        xyz="0 0 0"
        rpy="0 0 0" />
      <geometry>
        <mesh
          filename="../../meshes/Alicia_D_v5_6/gripper_50mm/Link1.STL" />
      </geometry>
    </collision>
  </link>
  <joint
    name="Joint1"
    type="revolute">
    <origin
      xyz="0 0 0.1295"
      rpy="0 0 0" />
    <parent
      link="base_link" />
    <child
      link="Link1" />
    <axis
      xyz="0 0 1" />
    <limit
      lower="-2.16"
      upper="2.16"
      effort="5"
      velocity="12" />
  </joint>
  <link
    name="Link2">
    <inertial>
      <origin
        xyz="0.15058869562262 0.000942409990636449 0.000567598737005813"
        rpy="0 0 0" />
      <mass
        value="0.207033693061786" />
      <inertia
        ixx="0.000128135500181764"
        ixy="1.19125955596776E-07"
        ixz="1.66696805664369E-06"
        iyy="0.00020570839060521"
        iyz="-3.50025103451336E-07"
        izz="0.000122721347332605" />
    </inertial>
    <visual>
      <origin
        xyz="0 0 0"
        rpy="0 0 0" />
      <geometry>
        <mesh
          filename="../../meshes/Alicia_D_v5_6/gripper_50mm/Link2.STL" />
      </geometry>
      <material
        name="">
        <color
          rgba="0.807843137254902 0.843137254901961 0.905882352941176 1" />
      </material>
    </visual>
    <collision>
      <origin
        xyz="0 0 0"
        rpy="0 0 0" />
      <geometry>
        <mesh
          filename="../../meshes/Alicia_D_v5_6/gripper_50mm/Link2.STL" />
      </geometry>
    </collision>
  </link>
  <joint
    name="Joint2"
    type="revolute">
    <origin
      xyz="0 0 0.0428699999999999"
      rpy="1.5707963267949 -1.5707963267949 0" />
    <parent
      link="Link1" />
    <child
      link="Link2" />
    <axis
      xyz="0 0 -1" />
    <limit
      lower="-1.57"
      upper="1.57"
      effort="5"
      velocity="12" />
  </joint>
  <link
    name="Link3">
    <inertial>
      <origin
        xyz="-0.00248143779329096 -0.0557863222033137 -0.000269721122389092"
        rpy="0 0 0" />
      <mass
        value="0.0845575636182319" />
      <inertia
        ixx="7.61918224458836E-05"
        ixy="-2.2649811089975E-06"
        ixz="-3.82299429105109E-07"
        iyy="2.87941474258093E-05"
        iyz="-5.38445186494266E-06"
        izz="8.04370522438273E-05" />
    </inertial>
    <visual>
      <origin
        xyz="0 0 0"
        rpy="0 0 0" />
      <geometry>
        <mesh
          filename="../../meshes/Alicia_D_v5_6/gripper_50mm/Link3.STL" />
      </geometry>
      <material
        name="">
        <color
          rgba="0.792156862745098 0.819607843137255 0.933333333333333 1" />
      </material>
    </visual>
    <collision>
      <origin
        xyz="0 0 0"
        rpy="0 0 0" />
      <geometry>
        <mesh
          filename="../../meshes/Alicia_D_v5_6/gripper_50mm/Link3.STL" />
      </geometry>
    </collision>
  </link>
  <joint
    name="Joint3"
    type="revolute">
    <origin
      xyz="0.223671302741224 0.0225916129580062 -5.00000000004269E-05"
      rpy="0 0 -2.35619455367747" />
    <parent
      link="Link2" />
    <child
      link="Link3" />
    <axis
      xyz="0 0 -1" />
    <limit
      lower="-0.5"
      upper="2.35619"
      effort="5"
      velocity="12" />
  </joint>
  <link
    name="Link4">
    <inertial>
      <origin
        xyz="-0.00029836550449891 -0.000601368925850489 -0.0659740391896737"
        rpy="0 0 0" />
      <mass
        value="0.0653695953286769" />
      <inertia
        ixx="7.03004188086356E-05"
        ixy="9.68417851216743E-09"
        ixz="-7.50131707418213E-07"
        iyy="6.87470297888139E-05"
        iyz="-4.45271906081802E-08"
        izz="1.68226189350756E-05" />
    </inertial>
    <visual>
      <origin
        xyz="0 0 0"
        rpy="0 0 0" />
      <geometry>
        <mesh
          filename="../../meshes/Alicia_D_v5_6/gripper_50mm/Link4.STL" />
      </geometry>
      <material
        name="">
        <color
          rgba="0.792156862745098 0.819607843137255 0.933333333333333 1" />
      </material>
    </visual>
    <collision>
      <origin
        xyz="0 0 0"
        rpy="0 0 0" />
      <geometry>
        <mesh
          filename="../../meshes/Alicia_D_v5_6/gripper_50mm/Link4.STL" />
      </geometry>
    </collision>
  </link>
  <joint
    name="Joint4"
    type="revolute">
    <origin
      xyz="0.00211000000000205 -0.0990000000000029 -0.000199999999999935"
      rpy="1.5707963267949 0 -3.14159265358979" />
    <parent
      link="Link3" />
    <child
      link="Link4" />
    <axis
      xyz="0 0 1" />
    <limit
      lower="-2.7925"
      upper="2.7925"
      effort="5"
      velocity="12" />
  </joint>
  <link
    name="Link5">
    <inertial>
      <origin
        xyz="-0.0113684233797882 -0.0308687469847002 0.000870449933405808"
        rpy="0 0 0" />
      <mass
        value="0.0507639016939355" />
      <inertia
        ixx="1.87701017076279E-05"
        ixy="-2.01098609907306E-06"
        ixz="5.15226500390501E-08"
        iyy="2.51021034466006E-05"
        iyz="-4.22412451727219E-08"
        izz="1.72571710040523E-05" />
    </inertial>
    <visual>
      <origin
        xyz="0 0 0"
        rpy="0 0 0" />
      <geometry>
        <mesh
          filename="../../meshes/Alicia_D_v5_6/gripper_50mm/Link5.STL" />
      </geometry>
      <material
        name="">
        <color
          rgba="0.792156862745098 0.819607843137255 0.933333333333333 1" />
      </material>
    </visual>
    <collision>
      <origin
        xyz="0 0 0"
        rpy="0 0 0" />
      <geometry>
        <mesh
          filename="../../meshes/Alicia_D_v5_6/gripper_50mm/Link5.STL" />
      </geometry>
    </collision>
  </link>
  <joint
    name="Joint5"
    type="revolute">
    <origin
      xyz="0 -0.000500000000000358 -0.12235"
      rpy="1.5707963267949 0 3.14159265358979" />
    <parent
      link="Link4" />
    <child
      link="Link5" />
    <axis
      xyz="0 0 -1" />
    <limit
      lower="-1.57"
      upper="1.57"
      effort="5"
      velocity="12" />
  </joint>
  <link
    name="Link6">
    <inertial>
      <origin
        xyz="-0.0274897808069792 -1.78816252605362E-05 0.0342551063501212"
        rpy="0 0 0" />
      <mass
        value="0.130364883326573" />
      <inertia
        ixx="7.59035802593379E-05"
        ixy="1.1454757042377E-08"
        ixz="-3.58078000042196E-06"
        iyy="3.53175388320522E-05"
        iyz="2.09250433426614E-08"
        izz="8.3197600961374E-05" />
    </inertial>
    <visual>
      <origin
        xyz="0 0 0"
        rpy="0 0 0" />
      <geometry>
        <mesh
          filename="../../meshes/Alicia_D_v5_6/gripper_50mm/Link6.STL" />
      </geometry>
      <material
        name="">
        <color
          rgba="0.592156862745098 0.666666666666667 0.682352941176471 1" />
      </material>
    </visual>
    <collision>
      <origin
        xyz="0 0 0"
        rpy="0 0 0" />
      <geometry>
        <mesh
          filename="../../meshes/Alicia_D_v5_6/gripper_50mm/Link6.STL" />
      </geometry>
    </collision>
  </link>
  <joint
    name="Joint6"
    type="revolute">
    <origin
      xyz="-0.00385 -0.0575 0.001"
      rpy="1.5708 0 0" />
    <parent
      link="Link5" />
    <child
      link="Link6" />
    <axis
      xyz="0 0 -1" />
    <limit
      lower="-3.14"
      upper="3.14"
      effort="5"
      velocity="12" />
  </joint>
  <link
    name="Link7">
    <inertial>
      <origin
        xyz="-2.97087515144234E-08 -0.0434087591943531 0.0106558526512254"
        rpy="0 0 0" />
      <mass
        value="0.0256461121677846" />
      <inertia
        ixx="6.46830326573713E-06"
        ixy="2.39543800976369E-11"
        ixz="4.6372130603958E-12"
        iyy="5.13428741941764E-06"
        iyz="1.26432048814165E-06"
        izz="8.03606347912528E-06" />
    </inertial>
    <visual>
      <origin
        xyz="0 0 0"
        rpy="0 0 0" />
      <geometry>
        <mesh
          filename="../../meshes/Alicia_D_v5_6/gripper_50mm/Link7.STL" />
      </geometry>
      <material
        name="">
        <color
          rgba="0.592156862745098 0.666666666666667 0.682352941176471 1" />
      </material>
    </visual>
    <collision>
      <origin
        xyz="0 0 0"
        rpy="0 0 0" />
      <geometry>
        <mesh
          filename="../../meshes/Alicia_D_v5_6/gripper_50mm/Link7.STL" />
      </geometry>
    </collision>
  </link>
  <joint
    name="left_finger"
    type="prismatic">
    <origin
      xyz="0.0002 -0.025469 0.13098"
      rpy="1.5708 0 0" />
    <parent
      link="Link6" />
    <child
      link="Link7" />
    <axis
      xyz="0 0 1" />
    <limit
      lower="-0.025"
      upper="0"
      effort="5"
      velocity="10" />
  </joint>
  <link
    name="Link8">
    <inertial>
      <origin
        xyz="2.97087527356688E-08 0.0434087591943507 0.0106558526512254"
        rpy="0 0 0" />
      <mass
        value="0.0256461121677874" />
      <inertia
        ixx="6.46830326573822E-06"
        ixy="2.3954379824257E-11"
        ixz="-4.63721284179035E-12"
        iyy="5.13428741941821E-06"
        iyz="-1.26432048814209E-06"
        izz="8.03606347912602E-06" />
    </inertial>
    <visual>
      <origin
        xyz="0 0 0"
        rpy="0 0 0" />
      <geometry>
        <mesh
          filename="../../meshes/Alicia_D_v5_6/gripper_50mm/Link8.STL" />
      </geometry>
      <material
        name="">
        <color
          rgba="0.592156862745098 0.666666666666667 0.682352941176471 1" />
      </material>
    </visual>
    <collision>
      <origin
        xyz="0 0 0"
        rpy="0 0 0" />
      <geometry>
        <mesh
          filename="../../meshes/Alicia_D_v5_6/gripper_50mm/Link8.STL" />
      </geometry>
    </collision>
  </link>
  <joint
    name="right_finger"
    type="prismatic">
    <origin
      xyz="0.0002 0.025469 0.13098"
      rpy="-1.5708 0 0" />
    <parent
      link="Link6" />
    <child
      link="Link8" />
    <axis
      xyz="0 0 -1" />
    <limit
      lower="0"
      upper="0.025"
      effort="5"
      velocity="10" />
  </joint>


  <link
    name="tool0">
    <visual>
      <origin
        xyz="0 0 0"
        rpy="0 0 0" />
      <geometry>
        <sphere radius="0.005" /> <!-- Define a small sphere with radius 0.005m -->
      </geometry>
      <material
        name="green_virtual_sphere_material"> <!-- Material name for the virtual sphere -->
        <color
          rgba="0 1 0 1" /> <!-- Green color (R G B A), A=1 means opaque -->
      </material>
    </visual>
  </link>
  <joint
    name="Grasp2tool"
    type="fixed">
    <origin
      xyz="-0.0002 -0.0003 0.13118"
      rpy="0 0 0" />
    <parent
      link="Link6" />
    <child
      link="tool0" />
    <axis
      xyz="0 0 0" />
  </joint>

</robot>