<?xml version="1.0" encoding="utf-8"?>
<!-- This URDF was automatically created by SolidWorks to URDF Exporter! Originally created by Stephen Brawner (brawner@gmail.com) 
     Commit Version: 1.6.0-4-g7f85cfe  Build Version: 1.6.7995.38578
     For more information, please see http://wiki.ros.org/sw_urdf_exporter -->
<robot
  name="Alicia_M_v1_0">
  <mujoco>
    <compiler meshdir="../../meshes/Alicia_M_v1_0/gripper_100mm/" balanceinertia="true" discardvisual="false" />
  </mujoco>
  <link
    name="base_link">
    <inertial>
      <origin
        xyz="7.4519E-11 -0.037929 0.033794"
        rpy="0 0 0" />
      <mass
        value="0.17762" />
      <inertia
        ixx="0.00038702"
        ixy="1.5952E-13"
        ixz="1.0229E-12"
        iyy="0.00045801"
        iyz="-3.0785E-06"
        izz="0.00022443" />
    </inertial>
    <visual>
      <origin
        xyz="0 0 0"
        rpy="0 0 0" />
      <geometry>
        <mesh
          filename="../../meshes/Alicia_M_v1_0/gripper_100mm/base_link.STL" />
      </geometry>
      <material
        name="">
        <color
          rgba="0.79608 0.82353 0.93725 1" />
      </material>
    </visual>
    <collision>
      <origin
        xyz="0 0 0"
        rpy="0 0 0" />
      <geometry>
        <mesh
          filename="../../meshes/Alicia_M_v1_0/gripper_100mm/base_link.STL" />
      </geometry>
    </collision>
  </link>
  <link
    name="link1">
    <inertial>
      <origin
        xyz="0.00023895 -0.00092465 0.0061005"
        rpy="0 0 0" />
      <mass
        value="0.87143" />
      <inertia
        ixx="0.00029657"
        ixy="-2.3651E-07"
        ixz="-3.3861E-08"
        iyy="0.00033942"
        iyz="1.0662E-07"
        izz="0.0003321" />
    </inertial>
    <visual>
      <origin
        xyz="0 0 0"
        rpy="0 0 0" />
      <geometry>
        <mesh
          filename="../../meshes/Alicia_M_v1_0/gripper_100mm/link1.STL" />
      </geometry>
      <material
        name="">
        <color
          rgba="0.75294 0.75294 0.75294 1" />
      </material>
    </visual>
    <collision>
      <origin
        xyz="0 0 0"
        rpy="0 0 0" />
      <geometry>
        <mesh
          filename="../../meshes/Alicia_M_v1_0/gripper_100mm/link1.STL" />
      </geometry>
    </collision>
  </link>
  <joint
    name="joint1"
    type="revolute">
    <origin
      xyz="0 0 -0.005"
      rpy="0 0 1.5708" />
    <parent
      link="base_link" />
    <child
      link="link1" />
    <axis
      xyz="0 0 -1" />
    <limit
      lower="-1.57"
      upper="1.57"
      effort="5"
      velocity="5" />
  </joint>
  <link
    name="link2">
    <inertial>
      <origin
        xyz="0.023144 0.2135 0.0011514"
        rpy="0 0 0" />
      <mass
        value="0.74169" />
      <inertia
        ixx="0.00068926"
        ixy="-4.2901E-05"
        ixz="7.0424E-07"
        iyy="0.0002396"
        iyz="-5.041E-07"
        izz="0.00076321" />
    </inertial>
    <visual>
      <origin
        xyz="0 0 0"
        rpy="0 0 0" />
      <geometry>
        <mesh
          filename="../../meshes/Alicia_M_v1_0/gripper_100mm/link2.STL" />
      </geometry>
      <material
        name="">
        <color
          rgba="0.75294 0.75294 0.75294 1" />
      </material>
    </visual>
    <collision>
      <origin
        xyz="0 0 0"
        rpy="0 0 0" />
      <geometry>
        <mesh
          filename="../../meshes/Alicia_M_v1_0/gripper_100mm/link2.STL" />
      </geometry>
    </collision>
  </link>
  <joint
    name="joint2"
    type="revolute">
    <origin
      xyz="0 0 0.038"
      rpy="1.5708 0 0" />
    <parent
      link="link1" />
    <child
      link="link2" />
    <axis
      xyz="0 0 -1" />
    <limit
      lower="-1.57"
      upper="1.57"
      effort="5"
      velocity="5" />
  </joint>
  <link
    name="link3">
    <inertial>
      <origin
        xyz="-0.025847 0.066055 -0.00021768"
        rpy="0 0 0" />
      <mass
        value="0.43964" />
      <inertia
        ixx="0.0001276"
        ixy="9.6301E-06"
        ixz="-5.5154E-07"
        iyy="0.00017462"
        iyz="7.7102E-08"
        izz="0.00014778" />
    </inertial>
    <visual>
      <origin
        xyz="0 0 0"
        rpy="0 0 0" />
      <geometry>
        <mesh
          filename="../../meshes/Alicia_M_v1_0/gripper_100mm/link3.STL" />
      </geometry>
      <material
        name="">
        <color
          rgba="0.75294 0.75294 0.75294 1" />
      </material>
    </visual>
    <collision>
      <origin
        xyz="0 0 0"
        rpy="0 0 0" />
      <geometry>
        <mesh
          filename="../../meshes/Alicia_M_v1_0/gripper_100mm/link3.STL" />
      </geometry>
    </collision>
  </link>
  <joint
    name="joint3"
    type="revolute">
    <origin
      xyz="0.04 0.28185 0"
      rpy="0 0 0" />
    <parent
      link="link2" />
    <child
      link="link3" />
    <axis
      xyz="0 0 -1" />
    <limit lower="0" upper="3.14" effort="5" velocity="5" />
  </joint>
  <link
    name="link4">
    <inertial>
      <origin
        xyz="8.3016E-05 0.0011014 0.16836"
        rpy="0 0 0" />
      <mass
        value="0.48086" />
      <inertia
        ixx="0.00016407"
        ixy="3.826E-08"
        ixz="1.3081E-08"
        iyy="0.00020494"
        iyz="6.4732E-07"
        izz="0.00013579" />
    </inertial>
    <visual>
      <origin
        xyz="0 0 0"
        rpy="0 0 0" />
      <geometry>
        <mesh
          filename="../../meshes/Alicia_M_v1_0/gripper_100mm/link4.STL" />
      </geometry>
      <material
        name="">
        <color
          rgba="0.75294 0.75294 0.75294 1" />
      </material>
    </visual>
    <collision>
      <origin
        xyz="0 0 0"
        rpy="0 0 0" />
      <geometry>
        <mesh
          filename="../../meshes/Alicia_M_v1_0/gripper_100mm/link4.STL" />
      </geometry>
    </collision>
  </link>
  <joint
    name="joint4"
    type="revolute">
    <origin
      xyz="-0.028222 0.046416 0"
      rpy="-1.5708 0 0" />
    <parent
      link="link3" />
    <child
      link="link4" />
    <axis
      xyz="0 0 1" />
    <limit
      lower="-1.57"
      upper="1.57"
      effort="5"
      velocity="5" />
  </joint>
  <link
    name="link5">
    <inertial>
      <origin
        xyz="4.2411E-05 0.052127 0.0026291"
        rpy="0 0 0" />
      <mass
        value="0.36501" />
      <inertia
        ixx="9.8752E-05"
        ixy="8.2168E-08"
        ixz="1.0205E-07"
        iyy="0.00013865"
        iyz="1.5201E-07"
        izz="0.00010578" />
    </inertial>
    <visual>
      <origin
        xyz="0 0 0"
        rpy="0 0 0" />
      <geometry>
        <mesh
          filename="../../meshes/Alicia_M_v1_0/gripper_100mm/link5.STL" />
      </geometry>
      <material
        name="">
        <color
          rgba="0.75294 0.75294 0.75294 1" />
      </material>
    </visual>
    <collision>
      <origin
        xyz="0 0 0"
        rpy="0 0 0" />
      <geometry>
        <mesh
          filename="../../meshes/Alicia_M_v1_0/gripper_100mm/link5.STL" />
      </geometry>
    </collision>
  </link>
  <joint
    name="joint5"
    type="revolute">
    <origin
      xyz="0 0 0.1942"
      rpy="1.5708 0 0" />
    <parent
      link="link4" />
    <child
      link="link5" />
    <axis
      xyz="0 0 -1" />
    <limit
      lower="-1.57"
      upper="1.57"
      effort="5"
      velocity="5" />
  </joint>
  <link
    name="link6">
    <inertial>
      <origin
        xyz="8.4698E-05 -0.00085164 0.033045"
        rpy="0 0 0" />
      <mass
        value="0.30235" />
      <inertia
        ixx="8.8358E-05"
        ixy="5.0322E-08"
        ixz="1.305E-07"
        iyy="8.8172E-05"
        iyz="1.661E-09"
        izz="0.00011982" />
    </inertial>
    <visual>
      <origin
        xyz="0 0 0"
        rpy="0 0 0" />
      <geometry>
        <mesh
          filename="../../meshes/Alicia_M_v1_0/gripper_100mm/link6.STL" />
      </geometry>
      <material
        name="">
        <color
          rgba="0.8902 0.8902 0.91373 1" />
      </material>
    </visual>
    <collision>
      <origin
        xyz="0 0 0"
        rpy="0 0 0" />
      <geometry>
        <mesh
          filename="../../meshes/Alicia_M_v1_0/gripper_100mm/link6.STL" />
      </geometry>
    </collision>
  </link>
  <joint
    name="joint6"
    type="revolute">
    <origin
      xyz="0 0.081 0"
      rpy="-1.5708 0 0" />
    <parent
      link="link5" />
    <child
      link="link6" />
    <axis
      xyz="0 0 -1" />
    <limit
      lower="-1.57"
      upper="1.57"
      effort="5"
      velocity="5" />
  </joint>
  <link
    name="grasp_link">
    <inertial>
      <origin
        xyz="-4.7244E-10 -0.00086666 -0.077544"
        rpy="0 0 0" />
      <mass
        value="0.094307" />
      <inertia
        ixx="0.00017348"
        ixy="5.4185E-12"
        ixz="3.3592E-14"
        iyy="7.8177E-06"
        iyz="1.1295E-08"
        izz="0.00017571" />
    </inertial>
    <visual>
      <origin
        xyz="0 0 0"
        rpy="0 0 0" />
      <geometry>
        <mesh
          filename="../../meshes/Alicia_M_v1_0/gripper_100mm/grasp_link.STL" />
      </geometry>
      <material
        name="">
        <color
          rgba="0.79608 0.82353 0.93725 1" />
      </material>
    </visual>
    <collision>
      <origin
        xyz="0 0 0"
        rpy="0 0 0" />
      <geometry>
        <mesh
          filename="../../meshes/Alicia_M_v1_0/gripper_100mm/grasp_link.STL" />
      </geometry>
    </collision>
  </link>
  <joint
    name="joint7_grasp"
    type="fixed">
    <origin
      xyz="0 0 0.151"
      rpy="0 0 0" />
    <parent
      link="link6" />
    <child
      link="grasp_link" />
    <axis
      xyz="0 0 0" />
  </joint>
  <link
    name="link8">
    <inertial>
      <origin
        xyz="-0.0051457 -0.058454 0.0078525"
        rpy="0 0 0" />
      <mass
        value="0.061665" />
      <inertia
        ixx="2.5567E-05"
        ixy="-1.0925E-06"
        ixz="-2.4316E-07"
        iyy="2.0213E-05"
        iyz="2.7427E-06"
        izz="2.0126E-05" />
    </inertial>
    <visual>
      <origin
        xyz="0 0 0"
        rpy="0 0 0" />
      <geometry>
        <mesh
          filename="../../meshes/Alicia_M_v1_0/gripper_100mm/link8.STL" />
      </geometry>
      <material
        name="">
        <color
          rgba="0.75294 0.75294 0.75294 1" />
      </material>
    </visual>
    <collision>
      <origin
        xyz="0 0 0"
        rpy="0 0 0" />
      <geometry>
        <mesh
          filename="../../meshes/Alicia_M_v1_0/gripper_100mm/link8.STL" />
      </geometry>
    </collision>
  </link>
  <joint
    name="joint8"
    type="prismatic">
    <origin
      xyz="0 -0.048341 0"
      rpy="1.5708 0 0" />
    <parent
      link="grasp_link" />
    <child
      link="link8" />
    <axis
      xyz="0 0 1" />
    <limit
      lower="-0.05"
      upper="0"
      effort="5"
      velocity="5" />
  </joint>
  <link
    name="link9">
    <inertial>
      <origin
        xyz="0.0051457 0.058454 0.0078525"
        rpy="0 0 0" />
      <mass
        value="0.061665" />
      <inertia
        ixx="2.5567E-05"
        ixy="-1.0925E-06"
        ixz="2.4316E-07"
        iyy="2.0213E-05"
        iyz="-2.7427E-06"
        izz="2.0126E-05" />
    </inertial>
    <visual>
      <origin
        xyz="0 0 0"
        rpy="0 0 0" />
      <geometry>
        <mesh
          filename="../../meshes/Alicia_M_v1_0/gripper_100mm/link9.STL" />
      </geometry>
      <material
        name="">
        <color
          rgba="0.75294 0.75294 0.75294 1" />
      </material>
    </visual>
    <collision>
      <origin
        xyz="0 0 0"
        rpy="0 0 0" />
      <geometry>
        <mesh
          filename="../../meshes/Alicia_M_v1_0/gripper_100mm/link9.STL" />
      </geometry>
    </collision>
  </link>
  <joint
    name="joint9"
    type="prismatic">
    <origin
      xyz="0 0.046641 0"
      rpy="-1.5708 0 0" />
    <parent
      link="grasp_link" />
    <child
      link="link9" />
    <axis
      xyz="0 0 -1" />
    <limit
      lower="0"
      upper="0.05"
      effort="5"
      velocity="5" />
  </joint>
</robot>