<mujoco model="Bessica-D_Covered">
  <compiler angle="radian" meshdir="../../meshes/Bessica_D_v1_0/withCover" />
  <statistic center="-0.012496 0.000424702 0.622672" extent="1.93611" meansize="0.179951" />

  <asset>
    <mesh name="base_link" file="base_link.STL" />
    <mesh name="base_link_collision_0" file="base_link1_0.obj" />
    <mesh name="base_link_collision_1" file="base_link1_1.obj" />
    <mesh name="base_link_collision_2" file="base_link1_2.obj" />
    <mesh name="base_link_collision_3" file="base_link1_3.obj" />
    <mesh name="base_link_collision_4" file="base_link1_4.obj" />
    <mesh name="base_link_collision_5" file="base_link1_5.obj" />
    <mesh name="base_link_collision_6" file="base_link1_6.obj" />
    <mesh name="base_link_collision_7" file="base_link1_7.obj" />
    <mesh name="base_link_collision_8" file="base_link1_8.obj" />
    <mesh name="base_link_collision_9" file="base_link1_9.obj" />
    <mesh name="base_link_collision_10" file="base_link1_10.obj" />
    <mesh name="base_link_collision_11" file="base_link1_11.obj" />
    <mesh name="base_link_collision_12" file="base_link1_12.obj" />
    <mesh name="base_link_collision_13" file="base_link1_13.obj" />
    <mesh name="base_link_collision_14" file="base_link1_14.obj" />
    <mesh name="base_link_collision_15" file="base_link1_15.obj" />
    <mesh name="base_link_collision_16" file="base_link1_16.obj" />
    <mesh name="base_link_collision_17" file="base_link1_17.obj" />
    <mesh name="base_link_collision_18" file="base_link1_18.obj" />
    <mesh name="base_link_collision_19" file="base_link1_19.obj" />
    <mesh name="right_arm_base_link" file="right_arm_base_link.STL" />
    <mesh name="right_arm_link1" file="right_arm_link1.STL" />
    <mesh name="right_arm_link2" file="right_arm_link2.STL" />
    <mesh name="right_arm_link3" file="right_arm_link3.STL" />
    <mesh name="right_arm_link4" file="right_arm_link4.STL" />
    <mesh name="right_arm_link5" file="right_arm_link5.STL" />
    <mesh name="right_arm_link6" file="right_arm_link6.STL" />
    <mesh name="right_arm_link7" file="right_arm_link7.STL" />
    <mesh name="right_arm_gripper_left_finger" file="right_arm_gripper_left_finger.STL" />
    <mesh name="right_arm_gripper_right_finger" file="right_arm_gripper_right_finger.STL" />
    <mesh name="left_arm_base_link" file="left_arm_base_link.STL" />
    <mesh name="left_arm_link1" file="left_arm_link1.STL" />
    <mesh name="left_arm_link2" file="left_arm_link2.STL" />
    <mesh name="left_arm_link3" file="left_arm_link3.STL" />
    <mesh name="left_arm_link4" file="left_arm_link4.STL" />
    <mesh name="left_arm_link5" file="left_arm_link5.STL" />
    <mesh name="left_arm_link6" file="left_arm_link6.STL" />
    <mesh name="left_arm_link7" file="left_arm_link7.STL" />
    <mesh name="left_arm_gripper_left_finger" file="left_arm_gripper_left_finger.STL" />
    <mesh name="left_arm_gripper_right_finger" file="left_arm_gripper_right_finger.STL" />
    <texture builtin="gradient" height="100" rgb1=".4 .5 .6" rgb2="0 0 0" type="skybox" width="100" />
    <texture builtin="checker" height="100" name="texplane" rgb1="1 1 1" rgb2=".8 .9 1" type="2d" width="100" />
    <material name="MatPlane" reflectance="0.5" texrepeat="1 1" texture="texplane" texuniform="true" />
    <material name="white" rgba="1 1 1 1" shininess="0.5" specular="0.1" />
    <material name="black" rgba="0.25 0.25 0.25 1" shininess="0.2" specular="0.05" />
    <material name="invisible" rgba="1 1 1 0" shininess="0" specular="0" />
  </asset>

  <worldbody>
    <geom conaffinity="1" condim="3" contype="1" friction="1 .1 .1" group="2" material="MatPlane" name="floor" pos="0 0 0" rgba="0.8 0.9 0.8 1" size="500 500 0.125" type="plane" />
    <light castshadow="false" cutoff="100" diffuse="1 1 1" dir="-0 0 -1.3" directional="true" exponent="1" pos="0 0 1.3" specular=".1 .1 .1" />
    <body name="base_link" pos="0 0 0">
      <inertial pos="0 0 0.051" mass="3.74344" diaginertia="0.00230599 0.00230599 0.00230599" />
      <geom pos="0 0 0" quat="0.5 0.5 0.5 0.5" type="mesh" contype="0" conaffinity="0" group="1" density="0" rgba="0.807843 0.843137 0.905882 1" mesh="base_link" />
      <!-- <geom pos="0 0 0" quat="0.5 0.5 0.5 0.5" type="mesh" rgba="0.807843 0.843137 0.905882 1" mesh="base_link" /> -->
      <geom pos="0 0 0" quat="0.5 0.5 0.5 0.5" type="mesh" rgba="0.807843 0.843137 0.905882 1" mesh="base_link_collision_0" />
      <geom pos="0 0 0" quat="0.5 0.5 0.5 0.5" type="mesh" rgba="0.807843 0.843137 0.905882 1" mesh="base_link_collision_1" />
      <geom pos="0 0 0" quat="0.5 0.5 0.5 0.5" type="mesh" rgba="0.807843 0.843137 0.905882 1" mesh="base_link_collision_2" />
      <geom pos="0 0 0" quat="0.5 0.5 0.5 0.5" type="mesh" rgba="0.807843 0.843137 0.905882 1" mesh="base_link_collision_3" />
      <geom pos="0 0 0" quat="0.5 0.5 0.5 0.5" type="mesh" rgba="0.807843 0.843137 0.905882 1" mesh="base_link_collision_4" />
      <geom pos="0 0 0" quat="0.5 0.5 0.5 0.5" type="mesh" rgba="0.807843 0.843137 0.905882 1" mesh="base_link_collision_5" />
      <geom pos="0 0 0" quat="0.5 0.5 0.5 0.5" type="mesh" rgba="0.807843 0.843137 0.905882 1" mesh="base_link_collision_6" />
      <geom pos="0 0 0" quat="0.5 0.5 0.5 0.5" type="mesh" rgba="0.807843 0.843137 0.905882 1" mesh="base_link_collision_7" />
      <geom pos="0 0 0" quat="0.5 0.5 0.5 0.5" type="mesh" rgba="0.807843 0.843137 0.905882 1" mesh="base_link_collision_8" />
      <geom pos="0 0 0" quat="0.5 0.5 0.5 0.5" type="mesh" rgba="0.807843 0.843137 0.905882 1" mesh="base_link_collision_9" />
      <geom pos="0 0 0" quat="0.5 0.5 0.5 0.5" type="mesh" rgba="0.807843 0.843137 0.905882 1" mesh="base_link_collision_10" />
      <geom pos="0 0 0" quat="0.5 0.5 0.5 0.5" type="mesh" rgba="0.807843 0.843137 0.905882 1" mesh="base_link_collision_11" />
      <geom pos="0 0 0" quat="0.5 0.5 0.5 0.5" type="mesh" rgba="0.807843 0.843137 0.905882 1" mesh="base_link_collision_12" />
      <geom pos="0 0 0" quat="0.5 0.5 0.5 0.5" type="mesh" rgba="0.807843 0.843137 0.905882 1" mesh="base_link_collision_13" />
      <geom pos="0 0 0" quat="0.5 0.5 0.5 0.5" type="mesh" rgba="0.807843 0.843137 0.905882 1" mesh="base_link_collision_14" />
      <geom pos="0 0 0" quat="0.5 0.5 0.5 0.5" type="mesh" rgba="0.807843 0.843137 0.905882 1" mesh="base_link_collision_15" />
      <geom pos="0 0 0" quat="0.5 0.5 0.5 0.5" type="mesh" rgba="0.807843 0.843137 0.905882 1" mesh="base_link_collision_16" />
      <geom pos="0 0 0" quat="0.5 0.5 0.5 0.5" type="mesh" rgba="0.807843 0.843137 0.905882 1" mesh="base_link_collision_17" />
      <geom pos="0 0 0" quat="0.5 0.5 0.5 0.5" type="mesh" rgba="0.807843 0.843137 0.905882 1" mesh="base_link_collision_18" />
      <geom pos="0 0 0" quat="0.5 0.5 0.5 0.5" type="mesh" rgba="0.807843 0.843137 0.905882 1" mesh="base_link_collision_19" />
      <geom pos="-0.1 0 1.015" quat="-0.5 0.5 0.5 -0.5" type="mesh" contype="0" conaffinity="0" group="1" density="0" rgba="0.592157 0.666667 0.682353 1" mesh="right_arm_base_link" />
      <geom pos="-0.1 0 1.015" quat="-0.5 0.5 0.5 -0.5" type="mesh" rgba="0.592157 0.666667 0.682353 1" mesh="right_arm_base_link" />
      <geom pos="0.1 0 1.015" quat="0.5 0.5 0.5 0.5" type="mesh" contype="0" conaffinity="0" group="1" density="0" rgba="0.592157 0.666667 0.682353 1" mesh="left_arm_base_link" />
      <geom pos="0.1 0 1.015" quat="0.5 0.5 0.5 0.5" type="mesh" rgba="0.592157 0.666667 0.682353 1" mesh="left_arm_base_link" />
      <body name="right_arm_link1" pos="-0.2145 0 1.015" quat="-0.5 -0.5 -0.5 -0.5">
        <inertial pos="-3.24276e-05 3.91803e-05 -0.0169208" quat="0.082841 0.69859 -0.0864725 0.705431" mass="0.315734" diaginertia="0.000465509 0.000358966 0.000355103" />
        <joint name="right_arm_joint1" pos="0 0 0" axis="0 0 -1" range="-2.14 2.14" actuatorfrcrange="-5 5" />
        <geom type="mesh" contype="0" conaffinity="0" group="1" density="0" rgba="0.796078 0.823529 0.937255 1" mesh="right_arm_link1" />
        <geom type="mesh" rgba="0.796078 0.823529 0.937255 1" mesh="right_arm_link1" />
        <body name="right_arm_link2" pos="0 0 -0.04287" quat="0.5 -0.5 0.5 -0.5">
          <inertial pos="0.0294209 0.000476964 0.000518959" quat="0.611373 0.419718 0.487356 0.461025" mass="0.0501482" diaginertia="1.62891e-05 1.57687e-05 7.39432e-06" />
          <joint name="right_arm_joint2" pos="0 0 0" axis="0 0 1" range="-0.214 2.14" actuatorfrcrange="-5 5" />
          <geom type="mesh" contype="0" conaffinity="0" group="1" density="0" rgba="0.807843 0.843137 0.905882 1" mesh="right_arm_link2" />
          <geom type="mesh" rgba="0.807843 0.843137 0.905882 1" mesh="right_arm_link2" />
          <body name="right_arm_link3" pos="0.06575 -0.0001 0.0004" quat="0.5 0.5 -0.5 -0.5">
            <inertial pos="-0.00598311 -4.94635e-05 -0.106126" quat="0.998642 -0.000134885 -0.0520953 -0.000162259" mass="0.368447" diaginertia="0.000674481 0.000603424 0.00036087" />
            <joint name="right_arm_joint3" pos="0 0 0" axis="0 0 -1" range="-0.9 0.9" actuatorfrcrange="-5 5" />
            <geom type="mesh" contype="0" conaffinity="0" group="1" density="0" rgba="0.807843 0.843137 0.905882 1" mesh="right_arm_link3" />
            <geom type="mesh" rgba="0.807843 0.843137 0.905882 1" mesh="right_arm_link3" />
            <body name="right_arm_link4" pos="0.00384 0 -0.20081" quat="0.707107 -0.707107 0 0">
              <inertial pos="-0.000541939 0.0284058 0.000370347" quat="0.639534 0.763579 -0.0839367 0.0299576" mass="0.0480071" diaginertia="1.64685e-05 1.57747e-05 7.22527e-06" />
              <joint name="right_arm_joint4" pos="0 0 0" axis="0 0 1" range="-2.14 0" actuatorfrcrange="-5 5" />
              <geom type="mesh" contype="0" conaffinity="0" group="1" density="0" rgba="0.807843 0.843137 0.905882 1" mesh="right_arm_link4" />
              <geom type="mesh" rgba="0.807843 0.843137 0.905882 1" mesh="right_arm_link4" />
              <body name="right_arm_link5" pos="0 0.06575 -0.0002" quat="0.707107 0.707107 0 0">
                <inertial pos="-0.00628109 0.000212854 -0.0715506" quat="0.702297 -0.0722103 -0.0708316 0.704661" mass="0.207077" diaginertia="0.000340616 0.000313554 0.000135687" />
                <joint name="right_arm_joint5" pos="0 0 0" axis="0 0 -1" range="-2.14 2.14" actuatorfrcrange="-5 5" />
                <geom type="mesh" contype="0" conaffinity="0" group="1" density="0" rgba="0.807843 0.843137 0.905882 1" mesh="right_arm_link5" />
                <geom type="mesh" rgba="0.807843 0.843137 0.905882 1" mesh="right_arm_link5" />
                <body name="right_arm_link6" pos="0.00379 5e-05 -0.1788" quat="0.707107 -0.707107 0 0">
                  <inertial pos="-0.000759195 0.0240066 5.58164e-05" quat="0.999602 -0.00398416 -0.000608784 -0.0279095" mass="0.0325623" diaginertia="1.56847e-05 1.2779e-05 9.25012e-06" />
                  <joint name="right_arm_joint6" pos="0 0 0" axis="0 0 1" range="-1.57 1.57" actuatorfrcrange="-5 5" />
                  <geom type="mesh" contype="0" conaffinity="0" group="1" density="0" rgba="0.807843 0.843137 0.905882 1" mesh="right_arm_link6" />
                  <geom type="mesh" rgba="0.807843 0.843137 0.905882 1" mesh="right_arm_link6" />
                  <body name="right_arm_link7" pos="0.0001 0.0556 0.0001" quat="0.5 -0.5 -0.5 0.5">
                    <inertial pos="0.00328545 7.5068e-05 0.0541056" quat="-0.000334602 0.888022 0.000164703 0.4598" mass="0.18191" diaginertia="0.00121978 0.00104138 0.000232198" />
                    <joint name="right_arm_joint7" pos="0 0 0" axis="0 0 1" range="-1.57 1.57" actuatorfrcrange="-5 5" />
                    <geom type="mesh" contype="0" conaffinity="0" group="1" density="0" rgba="0.592157 0.666667 0.682353 1" mesh="right_arm_link7" />
                    <geom type="mesh" rgba="0.592157 0.666667 0.682353 1" mesh="right_arm_link7" />
                    <geom pos="0.14128 0.0505 0.00015" quat="0.707105 0.707108 0 0" type="mesh" contype="0" conaffinity="0" group="1" density="0" rgba="0.592157 0.666667 0.682353 1"
                      mesh="right_arm_gripper_left_finger" />
                    <geom pos="0.14128 0.0505 0.00015" quat="0.707105 0.707108 0 0" type="mesh" rgba="0.592157 0.666667 0.682353 1" mesh="right_arm_gripper_left_finger" />
                    <geom pos="0.14128 -0.0505 0.00015" quat="0.707105 -0.707108 0 0" type="mesh" contype="0" conaffinity="0" group="1" density="0" rgba="0.592157 0.666667 0.682353 1"
                      mesh="right_arm_gripper_right_finger" />
                    <geom pos="0.14128 -0.0505 0.00015" quat="0.707105 -0.707108 0 0" type="mesh" rgba="0.592157 0.666667 0.682353 1" mesh="right_arm_gripper_right_finger" />
                    <!-- Gripper center site (between fingers) -->
                    <site name="right_gripper_center" pos="0.14128 0 0.00015" size="0.005" rgba="1 0 0 0.5" />
                  </body>
                </body>
              </body>
            </body>
          </body>
        </body>
      </body>
      <body name="left_arm_link1" pos="0.2145 0 1.015" quat="0.5 0.5 0.5 0.5">
        <inertial pos="3.24321e-05 3.91835e-05 0.0169208" quat="-0.0828376 0.69859 0.0864692 0.705431" mass="0.315734" diaginertia="0.000465509 0.000358966 0.000355103" />
        <joint name="left_arm_joint1" pos="0 0 0" axis="0 0 -1" range="-2.14 2.14" actuatorfrcrange="-5 5" />
        <geom type="mesh" contype="0" conaffinity="0" group="1" density="0" rgba="0.796078 0.823529 0.937255 1" mesh="left_arm_link1" />
        <geom type="mesh" rgba="0.796078 0.823529 0.937255 1" mesh="left_arm_link1" />
        <body name="left_arm_link2" pos="0 0 0.04287" quat="0.5 0.5 -0.5 -0.5">
          <inertial pos="0.0294209 0.000476964 0.000518959" quat="0.611373 0.419718 0.487356 0.461025" mass="0.0501482" diaginertia="1.62891e-05 1.57687e-05 7.39432e-06" />
          <joint name="left_arm_joint2" pos="0 0 0" axis="0 0 1" range="-0.214 2.14" actuatorfrcrange="-5 5" />
          <geom type="mesh" contype="0" conaffinity="0" group="1" density="0" rgba="0.807843 0.843137 0.905882 1" mesh="left_arm_link2" />
          <geom type="mesh" rgba="0.807843 0.843137 0.905882 1" mesh="left_arm_link2" />
          <body name="left_arm_link3" pos="0.06575 -0.0001 0.0004" quat="0.5 -0.5 0.5 -0.5">
            <inertial pos="-0.00607021 -7.96524e-05 0.105092" quat="0.998634 -0.00013549 0.0522467 0.00015883" mass="0.373333" diaginertia="0.000674969 0.000604631 0.00036243" />
            <joint name="left_arm_joint3" pos="0 0 0" axis="0 0 -1" range="-0.9 0.9" actuatorfrcrange="-5 5" />
            <geom type="mesh" contype="0" conaffinity="0" group="1" density="0" rgba="0.807843 0.843137 0.905882 1" mesh="left_arm_link3" />
            <geom type="mesh" rgba="0.807843 0.843137 0.905882 1" mesh="left_arm_link3" />
            <body name="left_arm_link4" pos="0.00384 0 0.20081" quat="0.707107 0.707107 0 0">
              <inertial pos="-0.000541939 0.0284058 0.000370347" quat="0.639534 0.763579 -0.0839367 0.0299576" mass="0.0480071" diaginertia="1.64685e-05 1.57747e-05 7.22527e-06" />
              <joint name="left_arm_joint4" pos="0 0 0" axis="0 0 1" range="-2.14 0" actuatorfrcrange="-5 5" />
              <geom type="mesh" contype="0" conaffinity="0" group="1" density="0" rgba="0.807843 0.843137 0.905882 1" mesh="left_arm_link4" />
              <geom type="mesh" rgba="0.807843 0.843137 0.905882 1" mesh="left_arm_link4" />
              <body name="left_arm_link5" pos="0 0.06575 -0.0002" quat="0.707107 -0.707107 0 0">
                <inertial pos="-0.00625733 -0.000212854 0.0763031" quat="0.704661 0.0708316 0.0722103 0.702297" mass="0.207077" diaginertia="0.000340616 0.000313554 0.000135687" />
                <joint name="left_arm_joint5" pos="0 0 0" axis="0 0 -1" range="-2.14 2.14" actuatorfrcrange="-5 5" />
                <geom type="mesh" contype="0" conaffinity="0" group="1" density="0" rgba="0.807843 0.843137 0.905882 1" mesh="left_arm_link5" />
                <geom type="mesh" rgba="0.807843 0.843137 0.905882 1" mesh="left_arm_link5" />
                <body name="left_arm_link6" pos="0.00379 -5e-05 0.1788" quat="0.707107 0.707107 0 0">
                  <inertial pos="-0.000759195 0.0240066 5.58164e-05" quat="0.999602 -0.00398416 -0.000608784 -0.0279095" mass="0.0325623" diaginertia="1.56847e-05 1.2779e-05 9.25012e-06" />
                  <joint name="left_arm_joint6" pos="0 0 0" axis="0 0 1" range="-1.57 1.57" actuatorfrcrange="-5 5" />
                  <geom type="mesh" contype="0" conaffinity="0" group="1" density="0" rgba="0.807843 0.843137 0.905882 1" mesh="left_arm_link6" />
                  <geom type="mesh" rgba="0.807843 0.843137 0.905882 1" mesh="left_arm_link6" />
                  <body name="left_arm_link7" pos="0.0001 0.0556 0.0001" quat="0.5 -0.5 -0.5 0.5">
                    <inertial pos="0.00385855 7.37729e-05 0.0532993" quat="-0.000326342 0.88874 0.000157892 0.458411" mass="0.185526" diaginertia="0.00122851 0.00105034 0.000232997" />
                    <joint name="left_arm_joint7" pos="0 0 0" axis="0 0 1" range="-1.57 1.57" actuatorfrcrange="-5 5" />
                    <geom type="mesh" contype="0" conaffinity="0" group="1" density="0" rgba="0.592157 0.666667 0.682353 1" mesh="left_arm_link7" />
                    <geom type="mesh" rgba="0.592157 0.666667 0.682353 1" mesh="left_arm_link7" />
                    <geom pos="0.14128 0.0505 0.00015" quat="0.707105 0.707108 0 0" type="mesh" contype="0" conaffinity="0" group="1" density="0" rgba="0.592157 0.666667 0.682353 1"
                      mesh="left_arm_gripper_left_finger" />
                    <geom pos="0.14128 0.0505 0.00015" quat="0.707105 0.707108 0 0" type="mesh" rgba="0.592157 0.666667 0.682353 1" mesh="left_arm_gripper_left_finger" />
                    <geom pos="0.14128 -0.0505 0.00015" quat="0.707105 -0.707108 0 0" type="mesh" contype="0" conaffinity="0" group="1" density="0" rgba="0.592157 0.666667 0.682353 1"
                      mesh="left_arm_gripper_right_finger" />
                    <geom pos="0.14128 -0.0505 0.00015" quat="0.707105 -0.707108 0 0" type="mesh" rgba="0.592157 0.666667 0.682353 1" mesh="left_arm_gripper_right_finger" />
                    <!-- Gripper center site (between fingers) -->
                    <site name="left_gripper_center" pos="0.14128 0 0.00015" size="0.005" rgba="0 0 1 0.5" />
                  </body>
                </body>
              </body>
            </body>
          </body>
        </body>
      </body>
    </body>
  </worldbody>

  <contact>
    <exclude body1="base_link" body2="left_arm_link1" />
    <exclude body1="left_arm_link1" body2="left_arm_link2" />
    <exclude body1="left_arm_link1" body2="left_arm_link3" />
    <exclude body1="left_arm_link2" body2="left_arm_link3" />
    <exclude body1="left_arm_link3" body2="left_arm_link4" />
    <exclude body1="left_arm_link4" body2="left_arm_link5" />
    <exclude body1="left_arm_link5" body2="left_arm_link6" />
    <exclude body1="left_arm_link6" body2="left_arm_link7" />
    <exclude body1="base_link" body2="right_arm_link1" />
    <exclude body1="right_arm_link1" body2="right_arm_link2" />
    <exclude body1="right_arm_link1" body2="right_arm_link3" />
    <exclude body1="right_arm_link2" body2="right_arm_link3" />
    <exclude body1="right_arm_link3" body2="right_arm_link4" />
    <exclude body1="right_arm_link4" body2="right_arm_link5" />
    <exclude body1="right_arm_link5" body2="right_arm_link6" />
    <exclude body1="right_arm_link6" body2="right_arm_link7" />
  </contact>
</mujoco>